Workbook

Sheet Sheet
A1: title | B1: creator | C1: subject | D1: publisher | E1: type | F1: digital object identifier | G1: physical object identifier | H1: URL | I1: language | J1: date | K1: relation | L1: coverage | M1: OCR URL | N1: OCR found?
A2: Abrégé de toutes les sciences, ou encyclopédie des enfants; mise dans un nouvel ordre,... | B2: Buqcellos, ...; Blocquel, Simon | C2: Kinder- und Jugendbücher; Historische Drucke | D2: Delarue ;; Castiaux | E2: monograph; text | F2: PPN766849139 | G2: PPN548262071 | H2: http://resolver.staatsbibliothek-berlin.de/SBB0000F13000000000 | I2: fre | J2: 1816 | K2: WegehauptDigital | L2: Paris; Lille | M2: empty | N2: no
A3: Naturgeschichte für Kinder | B3: Raff, Georg Christian | C3: Kinder- und Jugendbücher; Historische Drucke | D3: Sammer | E3: monograph; text | F3: PPN749770333 | G3: PPN279536941 | H3: http://resolver.staatsbibliothek-berlin.de/SBB0000E0AE00000000 | I3: ger | J3: 1846 | K3: WegehauptDigital | L3: Wien | M3: empty | N3: no
A4: Die Entstehung der Erde | B4: Kranz, Wilhelm; Meyer, Max Wilhelm | C4: Kinder- und Jugendbücher; Historische Drucke | D4: Paetel | E4: monograph; text | F4: PPN741297272 | G4: PPN276525892 | H4: http://resolver.staatsbibliothek-berlin.de/SBB0000CFAB00000000 | I4: ger | J4: 1907 | K4: WegehauptDigital | L4: Berlin | M4: https://content.staatsbibliothek-berlin.de/dc/741297272.ocr.zip | N4: yes
A5: Die Schulwerkstatt; ein Leitfaden zur Einführung der technischen Arbeiten in die Schule | B5: Barth, Ernst; Niederley, W. | C5: Kinder- und Jugendbücher; Historische Drucke | D5: Velhagen & Klasing | E5: monograph; text | F5: PPN745116574 | G5: PPN453868991 | H5: http://resolver.staatsbibliothek-berlin.de/SBB0000D59B00000000 | I5: ger | J5: 1882 | K5: WegehauptDigital | L5: Bielefeld [u.a.] | M5: https://content.staatsbibliothek-berlin.de/dc/745116574.ocr.zip | N5: yes
A6: Der junge Eisenbahnbauer; eine Anleitung zur Selbstherstellung von Modelleisenbahnen ; mit 118 Abb. | B6: Hermuth, Paul | C6: Kinder- und Jugendbücher; Historische Drucke | D6: Union Dt. Verl.-Gesellsch. | E6: monograph; text | F6: PPN744069432 | G6: PPN559338228 | H6: http://resolver.staatsbibliothek-berlin.de/SBB0000D52F00000000 | I6: ger | J6: 1916 | K6: WegehauptDigital | L6: Stuttgart [u.a.] | M6: https://content.staatsbibliothek-berlin.de/dc/744069432.ocr.zip | N6: yes
A7: Neuer Räthselschatz; für die Jugend zur Übung im Denken und zur belehrenden Unterhaltung | B7: Schäffer, W. | C7: Kinder- und Jugendbücher; Historische Drucke | D7: Oehmigke | E7: monograph; text | F7: PPN745271243 | G7: PPN573465517 | H7: http://resolver.staatsbibliothek-berlin.de/SBB0000D67F00000000 | I7: ger | J7: 1865 | K7: WegehauptDigital | L7: Neu-Ruppin | M7: https://content.staatsbibliothek-berlin.de/dc/745271243.ocr.zip | N7: yes
A8: Wander- und Spielbüchlein für Schüler und Schülerinnen | B8: Matzdorf, Paul | C8: Kinder- und Jugendbücher | D8: Strauch | E8: monograph; text | F8: PPN745123694 | G8: PPN56682809X | H8: http://resolver.staatsbibliothek-berlin.de/SBB0000D5AD00000000 | I8: ger | J8: 1910 | K8: WegehauptDigital | L8: Leipzig | M8: https://content.staatsbibliothek-berlin.de/dc/745123694.ocr.zip | N8: yes
A9: Causeries sur la science; illustrées de 94 gravures | B9: Tissandier, Gaston | C9: Kinder- und Jugendbücher; Historische Drucke | D9: Hachette | E9: monograph; text | F9: PPN745272312 | G9: PPN578011344 | H9: http://resolver.staatsbibliothek-berlin.de/SBB0000D68300000000 | I9: fre | J9: 1880 | K9: WegehauptDigital | L9: Paris | M9: https://content.staatsbibliothek-berlin.de/dc/745272312.ocr.zip | N9: yes
A10: Der unerschöpfliche Maître de Plaisir; oder die Kunst, in allen Jahreszeiten, im Freien und zu Hause, so wie an allen nur denkbaren Freudentagen die unterhaltendsten und belustigendsten Parthieen anzuordnen ; Enthaltend die besten Spiele, Lieder, Declamir- und Kunststücke, Räthsel, Charaden [et]c. Ein unentbehrliches Haus- und Handbuch für alle lebensfrohe deutsche Familien | C10: Kinder- und Jugendbücher; Historische Drucke | D10: Voigt | E10: monograph; text | F10: PPN767042255 | G10: PPN280073852 | H10: http://resolver.staatsbibliothek-berlin.de/SBB0000F1B700000000 | I10: ger | J10: 1822 | K10: WegehauptDigital | L10: Nordhausen; Sondershausen | M10: empty | N10: no
A11: Im Grünen oder Die kleinen Pflanzenfreunde; kleine Erzählungen aus dem Pflanzenreich | B11: Wagner, Hermann | C11: Kinder- und Jugendbücher | D11: Spamer | E11: monograph; text | F11: PPN743675703 | G11: PPN578788829 | H11: http://resolver.staatsbibliothek-berlin.de/SBB0000D31400000000 | I11: ger | J11: 1878 | K11: WegehauptDigital | L11: Leipzig | M11: https://content.staatsbibliothek-berlin.de/dc/743675703.ocr.zip | N11: yes
A12: Das Buch der Gesellschaftsspiele | B12: Weller, Hermine | C12: Kinder- und Jugendbücher | D12: Fischer | E12: monograph; text | F12: PPN745213553 | G12: PPN581117719 | H12: http://resolver.staatsbibliothek-berlin.de/SBB0000D65A00000000 | I12: ger | J12: 1910 | K12: WegehauptDigital | L12: Dresden | M12: https://content.staatsbibliothek-berlin.de/dc/745213553.ocr.zip | N12: yes
A13: Der gelehrte Spielkamerad; Anleitung für kleine Physiker, Chemiker, Botaniker und Naturfreunde zum Experimentieren, zur Anlage von Pflanzen-, Stein-, Muschel-, Insekten-, Schmetterling-, Vogel-, Briefmarken-Sammlungen ect. sowie zur Pflege der Hausthiere und des Hausgartens ; ein Supplement zum "Spielbuch für Knaben" | B13: Wagner, Hermann | C13: Kinder- und Jugendbücher | D13: Spamer | E13: monograph; text | F13: PPN74270906X | G13: PPN578814706 | H13: http://resolver.staatsbibliothek-berlin.de/SBB0000D2AA00000000 | I13: ger | J13: 1877 | K13: WegehauptDigital | L13: Leipzig | M13: https://content.staatsbibliothek-berlin.de/dc/74270906X.ocr.zip | N13: yes
A14: Des fleißigen Mädchens Koch-Büchlein für die Puppen-Küche | C14: Kinder- und Jugendbücher; Historische Drucke | D14: Meisel | E14: monograph; text | F14: PPN745432069 | G14: PPN278721036 | H14: http://resolver.staatsbibliothek-berlin.de/SBB0000D6A800000000 | I14: ger | J14: 1876 | K14: WegehauptDigital | L14: Leipzig; Herisau; Stuttgart | M14: https://content.staatsbibliothek-berlin.de/dc/745432069.ocr.zip | N14: yes
A15: Naturgeschichte für Kinder, von M. Georg Christian Raff, ordentlichen Lehrer der Geschichte und Geographie auf dem Lyceum zu Göttingen. Mit vierzehn Kupfertafeln | B15: Raff, Georg Christian | C15: Kinder- und Jugendbücher; Historische Drucke | E15: monograph; text | F15: PPN769119182 | G15: PPN571683770 | H15: http://resolver.staatsbibliothek-berlin.de/SBB0000F8A900000000 | I15: ger | J15: 1802 | K15: WegehauptDigital | L15: Frankfurt; Leipzig | M15: empty | N15: no
A16: Kleine Bilderschule für die Jugend | B16: Hausius, Karl Gottlob | C16: Kinder- und Jugendbücher; Historische Drucke | D16: Voß | E16: monograph; text | F16: PPN757417825 | G16: PPN55916422X | H16: http://resolver.staatsbibliothek-berlin.de/SBB0000ED8900000000 | I16: ger | J16: 1807 | K16: WegehauptDigital | L16: Leipzig | M16: empty | N16: no
A17: Vollständiges Giftbuch oder Unterricht, die Giftpflanzen, Giftminerale und Giftthiere kennen zu lernen, und Gesundheit und Leben gegen Vergiftungs-Gefahren sicher zu stellen | C17: Kinder- und Jugendbücher | D17: Voigt | E17: monograph; text | F17: PPN770137474 | G17: PPN406020620 | H17: http://resolver.staatsbibliothek-berlin.de/SBB0001031A00000000 | I17: ger | J17: 1817 | K17: WegehauptDigital | L17: Sondershausen | M17: empty | N17: no
A18: Schneiders Typen-Atlas; naturwissenschaftlich-geographischer Hand-Atlas für Schule und Haus | B18: Schneider, Oskar; Claudius, W.; Leutemann, H.; Mützel, G.; Seidel, C. F. | C18: Kinder- und Jugendbücher | D18: Meinhold | E18: monograph; text | F18: PPN743969359 | G18: PPN574227601 | H18: http://resolver.staatsbibliothek-berlin.de/SBB0000D4C500000000 | I18: ger | J18: 1885 | K18: WegehauptDigital | L18: Dresden | M18: https://content.staatsbibliothek-berlin.de/dc/743969359.ocr.zip | N18: yes
A19: Das Buch wunderbarer Erfindungen; in Schilderungen f. d. reifere Jugend : mit 125 Abb. u. 1 Titelbild. | B19: Thomas, Louis | C19: Kinder- und Jugendbücher; Historische Drucke | D19: Spamer | E19: monograph; text | F19: PPN756689090 | G19: PPN578154765 | H19: http://resolver.staatsbibliothek-berlin.de/SBB0000EBC100000000 | I19: ger | J19: 1860 | K19: WegehauptDigital | L19: Leipzig | M19: https://content.staatsbibliothek-berlin.de/dc/756689090.ocr.zip | N19: yes
A20: Naturgeschichte der Vögel; mit besonderer Berücksichtigung der in Deutschland vorkommenden Vögel und Belehrung über Zucht und Wartung der Haus- und Stubenvögel | B20: Abendroth, Carl | C20: Kinder- und Jugendbücher | D20: Baensch | E20: monograph; text | F20: PPN744053714 | G20: PPN538752823 | H20: http://resolver.staatsbibliothek-berlin.de/SBB0000D51E00000000 | I20: ger | J20: 1870 | K20: WegehauptDigital | L20: Leipzig | M20: https://content.staatsbibliothek-berlin.de/dc/744053714.ocr.zip | N20: yes
A21: Abrégé de toutes les sciences à l'usage des enfans de six ans jusqu' a douze; on y a joint un abrégé de l'histoire de Brandebourg | B21: Formey, Jean-Henri-Samuel | C21: Kinder- und Jugendbücher; Historische Drucke | D21: Horvath | E21: monograph; text | F21: PPN76623858X | G21: PPN557396433 | H21: http://resolver.staatsbibliothek-berlin.de/SBB0000EE5000000000 | I21: fre | J21: 1803 | K21: WegehauptDigital | L21: Potsdam | M21: empty | N21: no
A22: Jagden-Bilderbuch für die liebe Jugend; mit 9 lithographirten Darstellungen | C22: Kinder- und Jugendbücher | E22: monograph; text | F22: PPN770079113 | G22: PPN491349475 | H22: http://resolver.staatsbibliothek-berlin.de/SBB000102A700000000 | I22: ger | J22: 1860 | K22: WegehauptDigital | L22: [S.l.] | M22: https://content.staatsbibliothek-berlin.de/dc/770079113.ocr.zip | N22: yes
A23: Neues und bewährtes illustriertes Kochbuch für alle Stände; zuverlässige Anleitung zur Bereitung der verschiedenartigsten Speisen, Backwerke, Getränke etc. ; nach eigener, vieljähriger Erfahrung | B23: Davithis, H. | C23: Kinder- und Jugendbücher; Historische Drucke | D23: Enßlin und Laiblin | E23: monograph; text | F23: PPN745127495 | G23: PPN278540538 | H23: http://resolver.staatsbibliothek-berlin.de/SBB0000D5C100000000 | I23: ger | J23: 1905 | K23: WegehauptDigital | L23: Reutlingen | M23: https://content.staatsbibliothek-berlin.de/dc/745127495.ocr.zip | N23: yes
A24: An der Werkbank; Anleitung zur Handfertigkeit mit besonderer Berücksichtigung der Herstellung physikalischer Apparate ; für mittlere und reife Schüler | B24: Gscheidlen, Emanuel | C24: Kinder- und Jugendbücher; Historische Drucke | D24: Teubner | E24: monograph; text | F24: PPN745118615 | G24: PPN223999733 | H24: http://resolver.staatsbibliothek-berlin.de/SBB0000D59F00000000 | I24: ger | J24: 1912 | K24: WegehauptDigital | L24: Berlin; Leipzig | M24: https://content.staatsbibliothek-berlin.de/dc/745118615.ocr.zip | N24: yes
A25: Die Schöpfung der Erde; die Urwelt und die Urgeschöpfe bis zum Auftreten des Menschen ; Blicke in das Erdinnere ; Wanderungen in die Gebirgswelt, namentlich unsres Veterlandes, nach Kreuz und Quer ; mit reiferen Schülern unternommen | B25: Hintze, Eduard | C25: Kinder- und Jugendbücher | D25: Spamer | E25: monograph; text | F25: PPN742493695 | G25: PPN341499900 | H25: http://resolver.staatsbibliothek-berlin.de/SBB0000D1BE00000000 | I25: ger | J25: 1885 | K25: WegehauptDigital | L25: Leipzig, Berlin | M25: https://content.staatsbibliothek-berlin.de/dc/742493695.ocr.zip | N25: yes
A26: Der Weltspiegel; das Wissenswürdigste vom Weltgebäude, von der Erde, von den Völkern der Erde | B26: Hoffmann, Friedrich | C26: Kinder- und Jugendbücher; Historische Drucke | D26: Schmidt & Spring; Lithographische Anstalt von Engelhorn und Hochdanz | E26: monograph; text | F26: PPN766156990 | G26: PPN279154607 | H26: http://resolver.staatsbibliothek-berlin.de/SBB0000EE1D00000000 | I26: ger | J26: 1844 | K26: WegehauptDigital | L26: Stuttgart; Stuttgart | M26: empty | N26: no
A27: Naturgeschichte; der Jugend gewidmet | B27: Wagner, Hermann | C27: Kinder- und Jugendbücher | D27: Hoffmann | E27: monograph; text | F27: PPN770457983 | G27: PPN408013931 | H27: http://resolver.staatsbibliothek-berlin.de/SBB0001049700000000 | I27: ger | J27: 1870 | K27: WegehauptDigital | L27: Stuttgart | M27: https://content.staatsbibliothek-berlin.de/dc/770457983.ocr.zip | N27: yes
A28: Lehrbuch der Sternkunde; für Schulen und zum Selbstunterrichte | B28: Schubert, Gotthilf Heinrich | C28: Kinder- und Jugendbücher; Historische Drucke | D28: Weber | E28: monograph; text | F28: PPN750739150 | G28: PPN311822029 | H28: http://resolver.staatsbibliothek-berlin.de/SBB0000E3CF00000000 | I28: ger | J28: 1832 | K28: WegehauptDigital | L28: München | M28: empty | N28: no
A29: Leichte Künsteleien zum Vergnügen und zum Nutzen für Kinder und Nichtkinder; Ein Buch mannigfaltigen Inhaltes | B29: Rockstroh, Heinrich | C29: Kinder- und Jugendbücher; Historische Drucke | D29: Wittich | E29: monograph; text | F29: PPN767041380 | G29: PPN556113098 | H29: http://resolver.staatsbibliothek-berlin.de/SBB0000F1B600000000 | I29: ger | J29: 1819 | K29: WegehauptDigital | L29: Berlin | M29: empty | N29: no
A30: Europäische Bilder und Skizzen; zur Belehrung für die reifere Jugend | B30: Hoffmann, Julius; Hosemann, Theodor | C30: Kinder- und Jugendbücher | D30: Trewendt | E30: monograph; text | F30: PPN771014600 | G30: PPN265186358 | H30: http://resolver.staatsbibliothek-berlin.de/SBB00010A6400000000 | I30: ger | J30: 1858 | K30: WegehauptDigital | L30: Breslau | M30: https://content.staatsbibliothek-berlin.de/dc/771014600.ocr.zip | N30: yes
A31: Malerische Naturgeschichte der drei Reiche für Schule und Haus; Mit besonderer Beziehung auf das practische Leben bearbeitet von F[riedrich] W[ilhelm] Lindner; unter Mitwirkung von Dr. Fr. H. A. Lachmann | B31: Lachmann, Fr. H. A.; Lindner, Friedrich Wilhelm | C31: Kinder- und Jugendbücher; Historische Drucke | D31: Oehme & Müller | E31: monograph; text | F31: PPN770463371 | G31: PPN42077016X | H31: http://resolver.staatsbibliothek-berlin.de/SBB000104A200000000 | I31: ger | J31: 1840 | K31: WegehauptDigital | L31: Braunschweig | M31: empty | N31: no
A32: Allerlei schöne Bilderrätsel für Jung und Alt | C32: Kinder- und Jugendbücher; Historische Drucke | E32: monograph; text | F32: PPN74513548X | G32: PPN30847046X | H32: http://resolver.staatsbibliothek-berlin.de/SBB0000D5D100000000 | I32: ger | K32: WegehauptDigital | M32: https://content.staatsbibliothek-berlin.de/dc/74513548X.ocr.zip | N32: yes
A33: Der Hausbau; oder erste Begriffe von Staat und den vorzüglichsten Ständen, Handwerken, Fabriken, Künsten, Wissenschaften u. d. gl. für Kinder | B33: Werlich, August Karl Friedrich | C33: Kinder- und Jugendbücher; Historische Drucke | D33: Juniussische Buchhandlung | E33: monograph; text | F33: PPN756639891 | G33: PPN579566781 | H33: http://resolver.staatsbibliothek-berlin.de/SBB0000EB7900000000 | I33: ger | J33: 1804 | K33: WegehauptDigital | L33: Leipzig | M33: empty | N33: no
A34: Gemählde aus der Natur und dem Menschenleben, in einer Reihe von Schilderungen merkwürdiger Naturerscheinungen und gefahrvoller Reiseabentheuer; zum Nutzen und Vergnügen der Jugend | B34: Albertus, D. J. C. | C34: Kinder- und Jugendbücher | D34: Kaiser | E34: monograph; text | F34: PPN781283116 | G34: PPN541529498 | H34: http://resolver.staatsbibliothek-berlin.de/SBB0001555D00000000 | I34: ger | J34: 1830 | K34: WegehauptDigital | L34: Grätz | M34: empty | N34: no
A35: Kurzer Unterricht in der Naturwissenschaft für die Jugend | B35: Uihlein, Joseph | C35: Kinder- und Jugendbücher; Historische Drucke | D35: Andreä | E35: monograph; text | F35: PPN770157742 | G35: PPN366080202 | H35: http://resolver.staatsbibliothek-berlin.de/SBB0001033900000000 | I35: ger | J35: 1810 | K35: WegehauptDigital | L35: Frankfurt am Main | M35: empty | N35: no
A36: F. Martin's Naturgeschichte für die Jugend beiderlei Geschlechts; mit dreihundert Abbildungen und zwanzig Holzschnitten | B36: Kolb, Christian Friedrich August; Martin, F. | C36: Kinder- und Jugendbücher; Historische Drucke | D36: Schmidt & Spring | E36: monograph; text | F36: PPN741294397 | G36: PPN566740400 | H36: http://resolver.staatsbibliothek-berlin.de/SBB0000CFA500000000 | I36: ger | J36: 1880 | K36: WegehauptDigital | L36: Stuttgart | M36: https://content.staatsbibliothek-berlin.de/dc/741294397.ocr.zip | N36: yes
A37: Aus Werkstatt und Welt; eine Festgabe für die werkthätige Jugend dargereicht von Leipz. Fortbildungsschuldirektoren u.-Lehrern | C37: Kinder- und Jugendbücher; Historische Drucke | D37: Hahn; Schmidt | E37: monograph; text | F37: PPN770851347 | G37: PPN581182618 | H37: http://resolver.staatsbibliothek-berlin.de/SBB0001070300000000 | I37: ger | J37: 1901 | K37: WegehauptDigital | L37: Leipzig; Leipzig | M37: https://content.staatsbibliothek-berlin.de/dc/770851347.ocr.zip | N37: yes
A38: Mittheilungen aus dem Gebiet der Naturkunde und dem Menschenleben für die Jugend ; mit 25 col. Abb. | B38: Maukisch, Heinrich Eduard | C38: Kinder- und Jugendbücher; Historische Drucke | D38: Fischer u. Fuchs | E38: monograph; text | F38: PPN766619389 | G38: PPN566841444 | H38: http://resolver.staatsbibliothek-berlin.de/SBB0000F00A00000000 | I38: ger | J38: 1835 | K38: WegehauptDigital | L38: Leipzig | M38: empty | N38: no
A39: Čudesa bez čudesʹ; malenkaja fizika v priměnenii kʹ zabavamʹ/ sost. A. P. Nečaev. S 172 ris. | B39: Nečaev, A. P. | C39: Kinder- und Jugendbücher | D39: Lukovnikov | E39: monograph; text | F39: PPN742094227 | G39: PPN280334869 | H39: http://resolver.staatsbibliothek-berlin.de/SBB0000D0A100000000 | I39: rus | J39: 1911 | K39: WegehauptDigital | L39: Spb. [St. Petersburg] | M39: https://content.staatsbibliothek-berlin.de/dc/742094227.ocr.zip | N39: yes
A40: Nun rathe einmal!; Räthselbüchlein für Kinder von 5 - 10 Jahren | B40: Flinzer, Fedor | C40: Kinder- und Jugendbücher; Historische Drucke | D40: Focke | E40: monograph; text | F40: PPN745597041 | G40: PPN568651901 | H40: http://resolver.staatsbibliothek-berlin.de/SBB0000D6F200000000 | I40: ger | J40: 1864 | K40: WegehauptDigital | L40: Chemnitz | M40: https://content.staatsbibliothek-berlin.de/dc/745597041.ocr.zip | N40: yes
...

Sheet types
A3: Zeilenbeschriftungen | B3: Anzahl von type
A4: monograph; text | B4: 888
A5: no | B5: 409
A6: yes | B6: 479
A7: multivolume_work; text | B7: 288
A8: no | B8: 288
A9: periodical; text | B9: 1
A10: no | B10: 1
A11: periodical_volume; text | B11: 7
A12: no | B12: 7
A13: volume; text | B13: 825
A14: no | B14: 622
A15: yes | B15: 203
A16: (Leer)
A17: (Leer)
A18: Gesamtergebnis | B18: 2009

Sheet monographs and volumes
A1: title | B1: creator | C1: subject | D1: publisher | E1: type | F1: digital object identifier | G1: physical object identifier | H1: URL | I1: language | J1: date | K1: relation | L1: coverage | M1: OCR URL | N1: OCR found?
A2: Abrégé de toutes les sciences, ou encyclopédie des enfants; mise dans un nouvel ordre,... | B2: Buqcellos, ...; Blocquel, Simon | C2: Kinder- und Jugendbücher; Historische Drucke | D2: Delarue ;; Castiaux | E2: monograph; text | F2: PPN766849139 | G2: PPN548262071 | H2: http://resolver.staatsbibliothek-berlin.de/SBB0000F13000000000 | I2: fre | J2: 1816 | K2: WegehauptDigital | L2: Paris; Lille | M2: empty | N2: no
A3: Naturgeschichte für Kinder | B3: Raff, Georg Christian | C3: Kinder- und Jugendbücher; Historische Drucke | D3: Sammer | E3: monograph; text | F3: PPN749770333 | G3: PPN279536941 | H3: http://resolver.staatsbibliothek-berlin.de/SBB0000E0AE00000000 | I3: ger | J3: 1846 | K3: WegehauptDigital | L3: Wien | M3: empty | N3: no
A4: Die Entstehung der Erde | B4: Kranz, Wilhelm; Meyer, Max Wilhelm | C4: Kinder- und Jugendbücher; Historische Drucke | D4: Paetel | E4: monograph; text | F4: PPN741297272 | G4: PPN276525892 | H4: http://resolver.staatsbibliothek-berlin.de/SBB0000CFAB00000000 | I4: ger | J4: 1907 | K4: WegehauptDigital | L4: Berlin | M4: https://content.staatsbibliothek-berlin.de/dc/741297272.ocr.zip | N4: yes
A5: Die Schulwerkstatt; ein Leitfaden zur Einführung der technischen Arbeiten in die Schule | B5: Barth, Ernst; Niederley, W. | C5: Kinder- und Jugendbücher; Historische Drucke | D5: Velhagen & Klasing | E5: monograph; text | F5: PPN745116574 | G5: PPN453868991 | H5: http://resolver.staatsbibliothek-berlin.de/SBB0000D59B00000000 | I5: ger | J5: 1882 | K5: WegehauptDigital | L5: Bielefeld [u.a.] | M5: https://content.staatsbibliothek-berlin.de/dc/745116574.ocr.zip | N5: yes
A6: Der junge Eisenbahnbauer; eine Anleitung zur Selbstherstellung von Modelleisenbahnen ; mit 118 Abb. | B6: Hermuth, Paul | C6: Kinder- und Jugendbücher; Historische Drucke | D6: Union Dt. Verl.-Gesellsch. | E6: monograph; text | F6: PPN744069432 | G6: PPN559338228 | H6: http://resolver.staatsbibliothek-berlin.de/SBB0000D52F00000000 | I6: ger | J6: 1916 | K6: WegehauptDigital | L6: Stuttgart [u.a.] | M6: https://content.staatsbibliothek-berlin.de/dc/744069432.ocr.zip | N6: yes
A7: Neuer Räthselschatz; für die Jugend zur Übung im Denken und zur belehrenden Unterhaltung | B7: Schäffer, W. | C7: Kinder- und Jugendbücher; Historische Drucke | D7: Oehmigke | E7: monograph; text | F7: PPN745271243 | G7: PPN573465517 | H7: http://resolver.staatsbibliothek-berlin.de/SBB0000D67F00000000 | I7: ger | J7: 1865 | K7: WegehauptDigital | L7: Neu-Ruppin | M7: https://content.staatsbibliothek-berlin.de/dc/745271243.ocr.zip | N7: yes
A8: Wander- und Spielbüchlein für Schüler und Schülerinnen | B8: Matzdorf, Paul | C8: Kinder- und Jugendbücher | D8: Strauch | E8: monograph; text | F8: PPN745123694 | G8: PPN56682809X | H8: http://resolver.staatsbibliothek-berlin.de/SBB0000D5AD00000000 | I8: ger | J8: 1910 | K8: WegehauptDigital | L8: Leipzig | M8: https://content.staatsbibliothek-berlin.de/dc/745123694.ocr.zip | N8: yes
A9: Causeries sur la science; illustrées de 94 gravures | B9: Tissandier, Gaston | C9: Kinder- und Jugendbücher; Historische Drucke | D9: Hachette | E9: monograph; text | F9: PPN745272312 | G9: PPN578011344 | H9: http://resolver.staatsbibliothek-berlin.de/SBB0000D68300000000 | I9: fre | J9: 1880 | K9: WegehauptDigital | L9: Paris | M9: https://content.staatsbibliothek-berlin.de/dc/745272312.ocr.zip | N9: yes
A10: Der unerschöpfliche Maître de Plaisir; oder die Kunst, in allen Jahreszeiten, im Freien und zu Hause, so wie an allen nur denkbaren Freudentagen die unterhaltendsten und belustigendsten Parthieen anzuordnen ; Enthaltend die besten Spiele, Lieder, Declamir- und Kunststücke, Räthsel, Charaden [et]c. Ein unentbehrliches Haus- und Handbuch für alle lebensfrohe deutsche Familien | C10: Kinder- und Jugendbücher; Historische Drucke | D10: Voigt | E10: monograph; text | F10: PPN767042255 | G10: PPN280073852 | H10: http://resolver.staatsbibliothek-berlin.de/SBB0000F1B700000000 | I10: ger | J10: 1822 | K10: WegehauptDigital | L10: Nordhausen; Sondershausen | M10: empty | N10: no
A11: Im Grünen oder Die kleinen Pflanzenfreunde; kleine Erzählungen aus dem Pflanzenreich | B11: Wagner, Hermann | C11: Kinder- und Jugendbücher | D11: Spamer | E11: monograph; text | F11: PPN743675703 | G11: PPN578788829 | H11: http://resolver.staatsbibliothek-berlin.de/SBB0000D31400000000 | I11: ger | J11: 1878 | K11: WegehauptDigital | L11: Leipzig | M11: https://content.staatsbibliothek-berlin.de/dc/743675703.ocr.zip | N11: yes
A12: Das Buch der Gesellschaftsspiele | B12: Weller, Hermine | C12: Kinder- und Jugendbücher | D12: Fischer | E12: monograph; text | F12: PPN745213553 | G12: PPN581117719 | H12: http://resolver.staatsbibliothek-berlin.de/SBB0000D65A00000000 | I12: ger | J12: 1910 | K12: WegehauptDigital | L12: Dresden | M12: https://content.staatsbibliothek-berlin.de/dc/745213553.ocr.zip | N12: yes
A13: Der gelehrte Spielkamerad; Anleitung für kleine Physiker, Chemiker, Botaniker und Naturfreunde zum Experimentieren, zur Anlage von Pflanzen-, Stein-, Muschel-, Insekten-, Schmetterling-, Vogel-, Briefmarken-Sammlungen ect. sowie zur Pflege der Hausthiere und des Hausgartens ; ein Supplement zum "Spielbuch für Knaben" | B13: Wagner, Hermann | C13: Kinder- und Jugendbücher | D13: Spamer | E13: monograph; text | F13: PPN74270906X | G13: PPN578814706 | H13: http://resolver.staatsbibliothek-berlin.de/SBB0000D2AA00000000 | I13: ger | J13: 1877 | K13: WegehauptDigital | L13: Leipzig | M13: https://content.staatsbibliothek-berlin.de/dc/74270906X.ocr.zip | N13: yes
A14: Des fleißigen Mädchens Koch-Büchlein für die Puppen-Küche | C14: Kinder- und Jugendbücher; Historische Drucke | D14: Meisel | E14: monograph; text | F14: PPN745432069 | G14: PPN278721036 | H14: http://resolver.staatsbibliothek-berlin.de/SBB0000D6A800000000 | I14: ger | J14: 1876 | K14: WegehauptDigital | L14: Leipzig; Herisau; Stuttgart | M14: https://content.staatsbibliothek-berlin.de/dc/745432069.ocr.zip | N14: yes
A15: Naturgeschichte für Kinder, von M. Georg Christian Raff, ordentlichen Lehrer der Geschichte und Geographie auf dem Lyceum zu Göttingen. Mit vierzehn Kupfertafeln | B15: Raff, Georg Christian | C15: Kinder- und Jugendbücher; Historische Drucke | E15: monograph; text | F15: PPN769119182 | G15: PPN571683770 | H15: http://resolver.staatsbibliothek-berlin.de/SBB0000F8A900000000 | I15: ger | J15: 1802 | K15: WegehauptDigital | L15: Frankfurt; Leipzig | M15: empty | N15: no
A16: Kleine Bilderschule für die Jugend | B16: Hausius, Karl Gottlob | C16: Kinder- und Jugendbücher; Historische Drucke | D16: Voß | E16: monograph; text | F16: PPN757417825 | G16: PPN55916422X | H16: http://resolver.staatsbibliothek-berlin.de/SBB0000ED8900000000 | I16: ger | J16: 1807 | K16: WegehauptDigital | L16: Leipzig | M16: empty | N16: no
A17: Vollständiges Giftbuch oder Unterricht, die Giftpflanzen, Giftminerale und Giftthiere kennen zu lernen, und Gesundheit und Leben gegen Vergiftungs-Gefahren sicher zu stellen | C17: Kinder- und Jugendbücher | D17: Voigt | E17: monograph; text | F17: PPN770137474 | G17: PPN406020620 | H17: http://resolver.staatsbibliothek-berlin.de/SBB0001031A00000000 | I17: ger | J17: 1817 | K17: WegehauptDigital | L17: Sondershausen | M17: empty | N17: no
A18: Schneiders Typen-Atlas; naturwissenschaftlich-geographischer Hand-Atlas für Schule und Haus | B18: Schneider, Oskar; Claudius, W.; Leutemann, H.; Mützel, G.; Seidel, C. F. | C18: Kinder- und Jugendbücher | D18: Meinhold | E18: monograph; text | F18: PPN743969359 | G18: PPN574227601 | H18: http://resolver.staatsbibliothek-berlin.de/SBB0000D4C500000000 | I18: ger | J18: 1885 | K18: WegehauptDigital | L18: Dresden | M18: https://content.staatsbibliothek-berlin.de/dc/743969359.ocr.zip | N18: yes
A19: Das Buch wunderbarer Erfindungen; in Schilderungen f. d. reifere Jugend : mit 125 Abb. u. 1 Titelbild. | B19: Thomas, Louis | C19: Kinder- und Jugendbücher; Historische Drucke | D19: Spamer | E19: monograph; text | F19: PPN756689090 | G19: PPN578154765 | H19: http://resolver.staatsbibliothek-berlin.de/SBB0000EBC100000000 | I19: ger | J19: 1860 | K19: WegehauptDigital | L19: Leipzig | M19: https://content.staatsbibliothek-berlin.de/dc/756689090.ocr.zip | N19: yes
A20: Naturgeschichte der Vögel; mit besonderer Berücksichtigung der in Deutschland vorkommenden Vögel und Belehrung über Zucht und Wartung der Haus- und Stubenvögel | B20: Abendroth, Carl | C20: Kinder- und Jugendbücher | D20: Baensch | E20: monograph; text | F20: PPN744053714 | G20: PPN538752823 | H20: http://resolver.staatsbibliothek-berlin.de/SBB0000D51E00000000 | I20: ger | J20: 1870 | K20: WegehauptDigital | L20: Leipzig | M20: https://content.staatsbibliothek-berlin.de/dc/744053714.ocr.zip | N20: yes
A21: Abrégé de toutes les sciences à l'usage des enfans de six ans jusqu' a douze; on y a joint un abrégé de l'histoire de Brandebourg | B21: Formey, Jean-Henri-Samuel | C21: Kinder- und Jugendbücher; Historische Drucke | D21: Horvath | E21: monograph; text | F21: PPN76623858X | G21: PPN557396433 | H21: http://resolver.staatsbibliothek-berlin.de/SBB0000EE5000000000 | I21: fre | J21: 1803 | K21: WegehauptDigital | L21: Potsdam | M21: empty | N21: no
A22: Jagden-Bilderbuch für die liebe Jugend; mit 9 lithographirten Darstellungen | C22: Kinder- und Jugendbücher | E22: monograph; text | F22: PPN770079113 | G22: PPN491349475 | H22: http://resolver.staatsbibliothek-berlin.de/SBB000102A700000000 | I22: ger | J22: 1860 | K22: WegehauptDigital | L22: [S.l.] | M22: https://content.staatsbibliothek-berlin.de/dc/770079113.ocr.zip | N22: yes
A23: Neues und bewährtes illustriertes Kochbuch für alle Stände; zuverlässige Anleitung zur Bereitung der verschiedenartigsten Speisen, Backwerke, Getränke etc. ; nach eigener, vieljähriger Erfahrung | B23: Davithis, H. | C23: Kinder- und Jugendbücher; Historische Drucke | D23: Enßlin und Laiblin | E23: monograph; text | F23: PPN745127495 | G23: PPN278540538 | H23: http://resolver.staatsbibliothek-berlin.de/SBB0000D5C100000000 | I23: ger | J23: 1905 | K23: WegehauptDigital | L23: Reutlingen | M23: https://content.staatsbibliothek-berlin.de/dc/745127495.ocr.zip | N23: yes
A24: An der Werkbank; Anleitung zur Handfertigkeit mit besonderer Berücksichtigung der Herstellung physikalischer Apparate ; für mittlere und reife Schüler | B24: Gscheidlen, Emanuel | C24: Kinder- und Jugendbücher; Historische Drucke | D24: Teubner | E24: monograph; text | F24: PPN745118615 | G24: PPN223999733 | H24: http://resolver.staatsbibliothek-berlin.de/SBB0000D59F00000000 | I24: ger | J24: 1912 | K24: WegehauptDigital | L24: Berlin; Leipzig | M24: https://content.staatsbibliothek-berlin.de/dc/745118615.ocr.zip | N24: yes
A25: Die Schöpfung der Erde; die Urwelt und die Urgeschöpfe bis zum Auftreten des Menschen ; Blicke in das Erdinnere ; Wanderungen in die Gebirgswelt, namentlich unsres Veterlandes, nach Kreuz und Quer ; mit reiferen Schülern unternommen | B25: Hintze, Eduard | C25: Kinder- und Jugendbücher | D25: Spamer | E25: monograph; text | F25: PPN742493695 | G25: PPN341499900 | H25: http://resolver.staatsbibliothek-berlin.de/SBB0000D1BE00000000 | I25: ger | J25: 1885 | K25: WegehauptDigital | L25: Leipzig, Berlin | M25: https://content.staatsbibliothek-berlin.de/dc/742493695.ocr.zip | N25: yes
A26: Der Weltspiegel; das Wissenswürdigste vom Weltgebäude, von der Erde, von den Völkern der Erde | B26: Hoffmann, Friedrich | C26: Kinder- und Jugendbücher; Historische Drucke | D26: Schmidt & Spring; Lithographische Anstalt von Engelhorn und Hochdanz | E26: monograph; text | F26: PPN766156990 | G26: PPN279154607 | H26: http://resolver.staatsbibliothek-berlin.de/SBB0000EE1D00000000 | I26: ger | J26: 1844 | K26: WegehauptDigital | L26: Stuttgart; Stuttgart | M26: empty | N26: no
A27: Naturgeschichte; der Jugend gewidmet | B27: Wagner, Hermann | C27: Kinder- und Jugendbücher | D27: Hoffmann | E27: monograph; text | F27: PPN770457983 | G27: PPN408013931 | H27: http://resolver.staatsbibliothek-berlin.de/SBB0001049700000000 | I27: ger | J27: 1870 | K27: WegehauptDigital | L27: Stuttgart | M27: https://content.staatsbibliothek-berlin.de/dc/770457983.ocr.zip | N27: yes
A28: Lehrbuch der Sternkunde; für Schulen und zum Selbstunterrichte | B28: Schubert, Gotthilf Heinrich | C28: Kinder- und Jugendbücher; Historische Drucke | D28: Weber | E28: monograph; text | F28: PPN750739150 | G28: PPN311822029 | H28: http://resolver.staatsbibliothek-berlin.de/SBB0000E3CF00000000 | I28: ger | J28: 1832 | K28: WegehauptDigital | L28: München | M28: empty | N28: no
A29: Leichte Künsteleien zum Vergnügen und zum Nutzen für Kinder und Nichtkinder; Ein Buch mannigfaltigen Inhaltes | B29: Rockstroh, Heinrich | C29: Kinder- und Jugendbücher; Historische Drucke | D29: Wittich | E29: monograph; text | F29: PPN767041380 | G29: PPN556113098 | H29: http://resolver.staatsbibliothek-berlin.de/SBB0000F1B600000000 | I29: ger | J29: 1819 | K29: WegehauptDigital | L29: Berlin | M29: empty | N29: no
A30: Europäische Bilder und Skizzen; zur Belehrung für die reifere Jugend | B30: Hoffmann, Julius; Hosemann, Theodor | C30: Kinder- und Jugendbücher | D30: Trewendt | E30: monograph; text | F30: PPN771014600 | G30: PPN265186358 | H30: http://resolver.staatsbibliothek-berlin.de/SBB00010A6400000000 | I30: ger | J30: 1858 | K30: WegehauptDigital | L30: Breslau | M30: https://content.staatsbibliothek-berlin.de/dc/771014600.ocr.zip | N30: yes
A31: Malerische Naturgeschichte der drei Reiche für Schule und Haus; Mit besonderer Beziehung auf das practische Leben bearbeitet von F[riedrich] W[ilhelm] Lindner; unter Mitwirkung von Dr. Fr. H. A. Lachmann | B31: Lachmann, Fr. H. A.; Lindner, Friedrich Wilhelm | C31: Kinder- und Jugendbücher; Historische Drucke | D31: Oehme & Müller | E31: monograph; text | F31: PPN770463371 | G31: PPN42077016X | H31: http://resolver.staatsbibliothek-berlin.de/SBB000104A200000000 | I31: ger | J31: 1840 | K31: WegehauptDigital | L31: Braunschweig | M31: empty | N31: no
A32: Allerlei schöne Bilderrätsel für Jung und Alt | C32: Kinder- und Jugendbücher; Historische Drucke | E32: monograph; text | F32: PPN74513548X | G32: PPN30847046X | H32: http://resolver.staatsbibliothek-berlin.de/SBB0000D5D100000000 | I32: ger | K32: WegehauptDigital | M32: https://content.staatsbibliothek-berlin.de/dc/74513548X.ocr.zip | N32: yes
A33: Der Hausbau; oder erste Begriffe von Staat und den vorzüglichsten Ständen, Handwerken, Fabriken, Künsten, Wissenschaften u. d. gl. für Kinder | B33: Werlich, August Karl Friedrich | C33: Kinder- und Jugendbücher; Historische Drucke | D33: Juniussische Buchhandlung | E33: monograph; text | F33: PPN756639891 | G33: PPN579566781 | H33: http://resolver.staatsbibliothek-berlin.de/SBB0000EB7900000000 | I33: ger | J33: 1804 | K33: WegehauptDigital | L33: Leipzig | M33: empty | N33: no
A34: Gemählde aus der Natur und dem Menschenleben, in einer Reihe von Schilderungen merkwürdiger Naturerscheinungen und gefahrvoller Reiseabentheuer; zum Nutzen und Vergnügen der Jugend | B34: Albertus, D. J. C. | C34: Kinder- und Jugendbücher | D34: Kaiser | E34: monograph; text | F34: PPN781283116 | G34: PPN541529498 | H34: http://resolver.staatsbibliothek-berlin.de/SBB0001555D00000000 | I34: ger | J34: 1830 | K34: WegehauptDigital | L34: Grätz | M34: empty | N34: no
A35: Kurzer Unterricht in der Naturwissenschaft für die Jugend | B35: Uihlein, Joseph | C35: Kinder- und Jugendbücher; Historische Drucke | D35: Andreä | E35: monograph; text | F35: PPN770157742 | G35: PPN366080202 | H35: http://resolver.staatsbibliothek-berlin.de/SBB0001033900000000 | I35: ger | J35: 1810 | K35: WegehauptDigital | L35: Frankfurt am Main | M35: empty | N35: no
A36: F. Martin's Naturgeschichte für die Jugend beiderlei Geschlechts; mit dreihundert Abbildungen und zwanzig Holzschnitten | B36: Kolb, Christian Friedrich August; Martin, F. | C36: Kinder- und Jugendbücher; Historische Drucke | D36: Schmidt & Spring | E36: monograph; text | F36: PPN741294397 | G36: PPN566740400 | H36: http://resolver.staatsbibliothek-berlin.de/SBB0000CFA500000000 | I36: ger | J36: 1880 | K36: WegehauptDigital | L36: Stuttgart | M36: https://content.staatsbibliothek-berlin.de/dc/741294397.ocr.zip | N36: yes
A37: Aus Werkstatt und Welt; eine Festgabe für die werkthätige Jugend dargereicht von Leipz. Fortbildungsschuldirektoren u.-Lehrern | C37: Kinder- und Jugendbücher; Historische Drucke | D37: Hahn; Schmidt | E37: monograph; text | F37: PPN770851347 | G37: PPN581182618 | H37: http://resolver.staatsbibliothek-berlin.de/SBB0001070300000000 | I37: ger | J37: 1901 | K37: WegehauptDigital | L37: Leipzig; Leipzig | M37: https://content.staatsbibliothek-berlin.de/dc/770851347.ocr.zip | N37: yes
A38: Mittheilungen aus dem Gebiet der Naturkunde und dem Menschenleben für die Jugend ; mit 25 col. Abb. | B38: Maukisch, Heinrich Eduard | C38: Kinder- und Jugendbücher; Historische Drucke | D38: Fischer u. Fuchs | E38: monograph; text | F38: PPN766619389 | G38: PPN566841444 | H38: http://resolver.staatsbibliothek-berlin.de/SBB0000F00A00000000 | I38: ger | J38: 1835 | K38: WegehauptDigital | L38: Leipzig | M38: empty | N38: no
A39: Čudesa bez čudesʹ; malenkaja fizika v priměnenii kʹ zabavamʹ/ sost. A. P. Nečaev. S 172 ris. | B39: Nečaev, A. P. | C39: Kinder- und Jugendbücher | D39: Lukovnikov | E39: monograph; text | F39: PPN742094227 | G39: PPN280334869 | H39: http://resolver.staatsbibliothek-berlin.de/SBB0000D0A100000000 | I39: rus | J39: 1911 | K39: WegehauptDigital | L39: Spb. [St. Petersburg] | M39: https://content.staatsbibliothek-berlin.de/dc/742094227.ocr.zip | N39: yes
A40: Nun rathe einmal!; Räthselbüchlein für Kinder von 5 - 10 Jahren | B40: Flinzer, Fedor | C40: Kinder- und Jugendbücher; Historische Drucke | D40: Focke | E40: monograph; text | F40: PPN745597041 | G40: PPN568651901 | H40: http://resolver.staatsbibliothek-berlin.de/SBB0000D6F200000000 | I40: ger | J40: 1864 | K40: WegehauptDigital | L40: Chemnitz | M40: https://content.staatsbibliothek-berlin.de/dc/745597041.ocr.zip | N40: yes
...

Sheet monographs_volumes titles
A3: Zeilenbeschriftungen | B3: Anzahl von title
A4: PPN387303650 | B4: 3
A5: Mit 20 Kupfertafeln | B5: 3
A6: PPN58178104X | B6: 2
A7: Was ein kleines Mädchen wissen muß | B7: 2
A8: PPN742529940 | B8: 2
A9: Physik in Bildern | B9: 2
A10: PPN582161126 | B10: 2
A11: July to december | B11: 2
A12: PPN574051384 | B12: 2
A13: Kurzes und leichtes Rechenbuch für Anfänger wie auch für Bürger- und Landschulen; Erster und zweiter Theil | B13: 2
A14: PPN766276414 | B14: 2
A15: Geschenk für meine Kinder, am Tage ihrer Verlobung oder Vollständiger Unterricht über die Erziehung der Jugend vom Keime an, bis in das mannbare Alter | B15: 2
... A3335: Gesamtergebnis | B3335: 1720

Sheet remove_dupl_monographs_vol
A1: title | B1: creator | C1: subject | D1: publisher | E1: type | F1: digital object identifier | G1: physical object identifier | H1: URL | I1: language | J1: date | K1: relation | L1: coverage | M1: OCR URL | N1: OCR found? | P1: Zeilenbeschriftungen | Q1: Anzahl von type
A2: Abrégé de toutes les sciences, ou encyclopédie des enfants; mise dans un nouvel ordre,... | B2: Buqcellos, ...; Blocquel, Simon | C2: Kinder- und Jugendbücher; Historische Drucke | D2: Delarue ;; Castiaux | E2: monograph; text | F2: PPN766849139 | G2: PPN548262071 | H2: http://resolver.staatsbibliothek-berlin.de/SBB0000F13000000000 | I2: fre | J2: 1816 | K2: WegehauptDigital | L2: Paris; Lille | M2: empty | N2: no | P2: monograph; text | Q2: 869
A3: Naturgeschichte für Kinder | B3: Raff, Georg Christian | C3: Kinder- und Jugendbücher; Historische Drucke | D3: Sammer | E3: monograph; text | F3: PPN749770333 | G3: PPN279536941 | H3: http://resolver.staatsbibliothek-berlin.de/SBB0000E0AE00000000 | I3: ger | J3: 1846 | K3: WegehauptDigital | L3: Wien | M3: empty | N3: no | P3: no | Q3: 395
A4: Die Entstehung der Erde | B4: Kranz, Wilhelm; Meyer, Max Wilhelm | C4: Kinder- und Jugendbücher; Historische Drucke | D4: Paetel | E4: monograph; text | F4: PPN741297272 | G4: PPN276525892 | H4: http://resolver.staatsbibliothek-berlin.de/SBB0000CFAB00000000 | I4: ger | J4: 1907 | K4: WegehauptDigital | L4: Berlin | M4: https://content.staatsbibliothek-berlin.de/dc/741297272.ocr.zip | N4: yes | P4: yes | Q4: 474
A5: Die Schulwerkstatt; ein Leitfaden zur Einführung der technischen Arbeiten in die Schule | B5: Barth, Ernst; Niederley, W. | C5: Kinder- und Jugendbücher; Historische Drucke | D5: Velhagen & Klasing | E5: monograph; text | F5: PPN745116574 | G5: PPN453868991 | H5: http://resolver.staatsbibliothek-berlin.de/SBB0000D59B00000000 | I5: ger | J5: 1882 | K5: WegehauptDigital | L5: Bielefeld [u.a.] | M5: https://content.staatsbibliothek-berlin.de/dc/745116574.ocr.zip | N5: yes | P5: periodical_volume; text | Q5: 5
A6: Der junge Eisenbahnbauer; eine Anleitung zur Selbstherstellung von Modelleisenbahnen ; mit 118 Abb. | B6: Hermuth, Paul | C6: Kinder- und Jugendbücher; Historische Drucke | D6: Union Dt. Verl.-Gesellsch. | E6: monograph; text | F6: PPN744069432 | G6: PPN559338228 | H6: http://resolver.staatsbibliothek-berlin.de/SBB0000D52F00000000 | I6: ger | J6: 1916 | K6: WegehauptDigital | L6: Stuttgart [u.a.] | M6: https://content.staatsbibliothek-berlin.de/dc/744069432.ocr.zip | N6: yes | P6: no | Q6: 5
A7: Neuer Räthselschatz; für die Jugend zur Übung im Denken und zur belehrenden Unterhaltung | B7: Schäffer, W. | C7: Kinder- und Jugendbücher; Historische Drucke | D7: Oehmigke | E7: monograph; text | F7: PPN745271243 | G7: PPN573465517 | H7: http://resolver.staatsbibliothek-berlin.de/SBB0000D67F00000000 | I7: ger | J7: 1865 | K7: WegehauptDigital | L7: Neu-Ruppin | M7: https://content.staatsbibliothek-berlin.de/dc/745271243.ocr.zip | N7: yes | P7: volume; text | Q7: 793
A8: Wander- und Spielbüchlein für Schüler und Schülerinnen | B8: Matzdorf, Paul | C8: Kinder- und Jugendbücher | D8: Strauch | E8: monograph; text | F8: PPN745123694 | G8: PPN56682809X | H8: http://resolver.staatsbibliothek-berlin.de/SBB0000D5AD00000000 | I8: ger | J8: 1910 | K8: WegehauptDigital | L8: Leipzig | M8: https://content.staatsbibliothek-berlin.de/dc/745123694.ocr.zip | N8: yes | P8: no | Q8: 599
A9: Causeries sur la science; illustrées de 94 gravures | B9: Tissandier, Gaston | C9: Kinder- und Jugendbücher; Historische Drucke | D9: Hachette | E9: monograph; text | F9: PPN745272312 | G9: PPN578011344 | H9: http://resolver.staatsbibliothek-berlin.de/SBB0000D68300000000 | I9: fre | J9: 1880 | K9: WegehauptDigital | L9: Paris | M9: https://content.staatsbibliothek-berlin.de/dc/745272312.ocr.zip | N9: yes | P9: yes | Q9: 194
A10: Der unerschöpfliche Maître de Plaisir; oder die Kunst, in allen Jahreszeiten, im Freien und zu Hause, so wie an allen nur denkbaren Freudentagen die unterhaltendsten und belustigendsten Parthieen anzuordnen ; Enthaltend die besten Spiele, Lieder, Declamir- und Kunststücke, Räthsel, Charaden [et]c. Ein unentbehrliches Haus- und Handbuch für alle lebensfrohe deutsche Familien | C10: Kinder- und Jugendbücher; Historische Drucke | D10: Voigt | E10: monograph; text | F10: PPN767042255 | G10: PPN280073852 | H10: http://resolver.staatsbibliothek-berlin.de/SBB0000F1B700000000 | I10: ger | J10: 1822 | K10: WegehauptDigital | L10: Nordhausen; Sondershausen | M10: empty | N10: no | P10: (Leer)
A11: Im Grünen oder Die kleinen Pflanzenfreunde; kleine Erzählungen aus dem Pflanzenreich | B11: Wagner, Hermann | C11: Kinder- und Jugendbücher | D11: Spamer | E11: monograph; text | F11: PPN743675703 | G11: PPN578788829 | H11: http://resolver.staatsbibliothek-berlin.de/SBB0000D31400000000 | I11: ger | J11: 1878 | K11: WegehauptDigital | L11: Leipzig | M11: https://content.staatsbibliothek-berlin.de/dc/743675703.ocr.zip | N11: yes | P11: (Leer)
A12: Das Buch der Gesellschaftsspiele | B12: Weller, Hermine | C12: Kinder- und Jugendbücher | D12: Fischer | E12: monograph; text | F12: PPN745213553 | G12: PPN581117719 | H12: http://resolver.staatsbibliothek-berlin.de/SBB0000D65A00000000 | I12: ger | J12: 1910 | K12: WegehauptDigital | L12: Dresden | M12: https://content.staatsbibliothek-berlin.de/dc/745213553.ocr.zip | N12: yes | P12: Gesamtergebnis | Q12: 1667
A13: Der gelehrte Spielkamerad; Anleitung für kleine Physiker, Chemiker, Botaniker und Naturfreunde zum Experimentieren, zur Anlage von Pflanzen-, Stein-, Muschel-, Insekten-, Schmetterling-, Vogel-, Briefmarken-Sammlungen ect. sowie zur Pflege der Hausthiere und des Hausgartens ; ein Supplement zum "Spielbuch für Knaben" | B13: Wagner, Hermann | C13: Kinder- und Jugendbücher | D13: Spamer | E13: monograph; text | F13: PPN74270906X | G13: PPN578814706 | H13: http://resolver.staatsbibliothek-berlin.de/SBB0000D2AA00000000 | I13: ger | J13: 1877 | K13: WegehauptDigital | L13: Leipzig | M13: https://content.staatsbibliothek-berlin.de/dc/74270906X.ocr.zip | N13: yes
A14: Des fleißigen Mädchens Koch-Büchlein für die Puppen-Küche | C14: Kinder- und Jugendbücher; Historische Drucke | D14: Meisel | E14: monograph; text | F14: PPN745432069 | G14: PPN278721036 | H14: http://resolver.staatsbibliothek-berlin.de/SBB0000D6A800000000 | I14: ger | J14: 1876 | K14: WegehauptDigital | L14: Leipzig; Herisau; Stuttgart | M14: https://content.staatsbibliothek-berlin.de/dc/745432069.ocr.zip | N14: yes
A15: Naturgeschichte für Kinder, von M. Georg Christian Raff, ordentlichen Lehrer der Geschichte und Geographie auf dem Lyceum zu Göttingen. Mit vierzehn Kupfertafeln | B15: Raff, Georg Christian | C15: Kinder- und Jugendbücher; Historische Drucke | E15: monograph; text | F15: PPN769119182 | G15: PPN571683770 | H15: http://resolver.staatsbibliothek-berlin.de/SBB0000F8A900000000 | I15: ger | J15: 1802 | K15: WegehauptDigital | L15: Frankfurt; Leipzig | M15: empty | N15: no
A16: Kleine Bilderschule für die Jugend | B16: Hausius, Karl Gottlob | C16: Kinder- und Jugendbücher; Historische Drucke | D16: Voß | E16: monograph; text | F16: PPN757417825 | G16: PPN55916422X | H16: http://resolver.staatsbibliothek-berlin.de/SBB0000ED8900000000 | I16: ger | J16: 1807 | K16: WegehauptDigital | L16: Leipzig | M16: empty | N16: no
A17: Vollständiges Giftbuch oder Unterricht, die Giftpflanzen, Giftminerale und Giftthiere kennen zu lernen, und Gesundheit und Leben gegen Vergiftungs-Gefahren sicher zu stellen | C17: Kinder- und Jugendbücher | D17: Voigt | E17: monograph; text | F17: PPN770137474 | G17: PPN406020620 | H17: http://resolver.staatsbibliothek-berlin.de/SBB0001031A00000000 | I17: ger | J17: 1817 | K17: WegehauptDigital | L17: Sondershausen | M17: empty | N17: no
A18: Schneiders Typen-Atlas; naturwissenschaftlich-geographischer Hand-Atlas für Schule und Haus | B18: Schneider, Oskar; Claudius, W.; Leutemann, H.; Mützel, G.; Seidel, C. F. | C18: Kinder- und Jugendbücher | D18: Meinhold | E18: monograph; text | F18: PPN743969359 | G18: PPN574227601 | H18: http://resolver.staatsbibliothek-berlin.de/SBB0000D4C500000000 | I18: ger | J18: 1885 | K18: WegehauptDigital | L18: Dresden | M18: https://content.staatsbibliothek-berlin.de/dc/743969359.ocr.zip | N18: yes
A19: Das Buch wunderbarer Erfindungen; in Schilderungen f. d. reifere Jugend : mit 125 Abb. u. 1 Titelbild. | B19: Thomas, Louis | C19: Kinder- und Jugendbücher; Historische Drucke | D19: Spamer | E19: monograph; text | F19: PPN756689090 | G19: PPN578154765 | H19: http://resolver.staatsbibliothek-berlin.de/SBB0000EBC100000000 | I19: ger | J19: 1860 | K19: WegehauptDigital | L19: Leipzig | M19: https://content.staatsbibliothek-berlin.de/dc/756689090.ocr.zip | N19: yes
A20: Naturgeschichte der Vögel; mit besonderer Berücksichtigung der in Deutschland vorkommenden Vögel und Belehrung über Zucht und Wartung der Haus- und Stubenvögel | B20: Abendroth, Carl | C20: Kinder- und Jugendbücher | D20: Baensch | E20: monograph; text | F20: PPN744053714 | G20: PPN538752823 | H20: http://resolver.staatsbibliothek-berlin.de/SBB0000D51E00000000 | I20: ger | J20: 1870 | K20: WegehauptDigital | L20: Leipzig | M20: https://content.staatsbibliothek-berlin.de/dc/744053714.ocr.zip | N20: yes
A21: Abrégé de toutes les sciences à l'usage des enfans de six ans jusqu' a douze; on y a joint un abrégé de l'histoire de Brandebourg | B21: Formey, Jean-Henri-Samuel | C21: Kinder- und Jugendbücher; Historische Drucke | D21: Horvath | E21: monograph; text | F21: PPN76623858X | G21: PPN557396433 | H21: http://resolver.staatsbibliothek-berlin.de/SBB0000EE5000000000 | I21: fre | J21: 1803 | K21: WegehauptDigital | L21: Potsdam | M21: empty | N21: no
A22: Jagden-Bilderbuch für die liebe Jugend; mit 9 lithographirten Darstellungen | C22: Kinder- und Jugendbücher | E22: monograph; text | F22: PPN770079113 | G22: PPN491349475 | H22: http://resolver.staatsbibliothek-berlin.de/SBB000102A700000000 | I22: ger | J22: 1860 | K22: WegehauptDigital | L22: [S.l.] | M22: https://content.staatsbibliothek-berlin.de/dc/770079113.ocr.zip | N22: yes
A23: Neues und bewährtes illustriertes Kochbuch für alle Stände; zuverlässige Anleitung zur Bereitung der verschiedenartigsten Speisen, Backwerke, Getränke etc. ; nach eigener, vieljähriger Erfahrung | B23: Davithis, H. | C23: Kinder- und Jugendbücher; Historische Drucke | D23: Enßlin und Laiblin | E23: monograph; text | F23: PPN745127495 | G23: PPN278540538 | H23: http://resolver.staatsbibliothek-berlin.de/SBB0000D5C100000000 | I23: ger | J23: 1905 | K23: WegehauptDigital | L23: Reutlingen | M23: https://content.staatsbibliothek-berlin.de/dc/745127495.ocr.zip | N23: yes
A24: An der Werkbank; Anleitung zur Handfertigkeit mit besonderer Berücksichtigung der Herstellung physikalischer Apparate ; für mittlere und reife Schüler | B24: Gscheidlen, Emanuel | C24: Kinder- und Jugendbücher; Historische Drucke | D24: Teubner | E24: monograph; text | F24: PPN745118615 | G24: PPN223999733 | H24: http://resolver.staatsbibliothek-berlin.de/SBB0000D59F00000000 | I24: ger | J24: 1912 | K24: WegehauptDigital | L24: Berlin; Leipzig | M24: https://content.staatsbibliothek-berlin.de/dc/745118615.ocr.zip | N24: yes
A25: Die Schöpfung der Erde; die Urwelt und die Urgeschöpfe bis zum Auftreten des Menschen ; Blicke in das Erdinnere ; Wanderungen in die Gebirgswelt, namentlich unsres Veterlandes, nach Kreuz und Quer ; mit reiferen Schülern unternommen | B25: Hintze, Eduard | C25: Kinder- und Jugendbücher | D25: Spamer | E25: monograph; text | F25: PPN742493695 | G25: PPN341499900 | H25: http://resolver.staatsbibliothek-berlin.de/SBB0000D1BE00000000 | I25: ger | J25: 1885 | K25: WegehauptDigital | L25: Leipzig, Berlin | M25: https://content.staatsbibliothek-berlin.de/dc/742493695.ocr.zip | N25: yes
A26: Der Weltspiegel; das Wissenswürdigste vom Weltgebäude, von der Erde, von den Völkern der Erde | B26: Hoffmann, Friedrich | C26: Kinder- und Jugendbücher; Historische Drucke | D26: Schmidt & Spring; Lithographische Anstalt von Engelhorn und Hochdanz | E26: monograph; text | F26: PPN766156990 | G26: PPN279154607 | H26: http://resolver.staatsbibliothek-berlin.de/SBB0000EE1D00000000 | I26: ger | J26: 1844 | K26: WegehauptDigital | L26: Stuttgart; Stuttgart | M26: empty | N26: no
A27: Naturgeschichte; der Jugend gewidmet | B27: Wagner, Hermann | C27: Kinder- und Jugendbücher | D27: Hoffmann | E27: monograph; text | F27: PPN770457983 | G27: PPN408013931 | H27: http://resolver.staatsbibliothek-berlin.de/SBB0001049700000000 | I27: ger | J27: 1870 | K27: WegehauptDigital | L27: Stuttgart | M27: https://content.staatsbibliothek-berlin.de/dc/770457983.ocr.zip | N27: yes
A28: Lehrbuch der Sternkunde; für Schulen und zum Selbstunterrichte | B28: Schubert, Gotthilf Heinrich | C28: Kinder- und Jugendbücher; Historische Drucke | D28: Weber | E28: monograph; text | F28: PPN750739150 | G28: PPN311822029 | H28: http://resolver.staatsbibliothek-berlin.de/SBB0000E3CF00000000 | I28: ger | J28: 1832 | K28: WegehauptDigital | L28: München | M28: empty | N28: no
A29: Leichte Künsteleien zum Vergnügen und zum Nutzen für Kinder und Nichtkinder; Ein Buch mannigfaltigen Inhaltes | B29: Rockstroh, Heinrich | C29: Kinder- und Jugendbücher; Historische Drucke | D29: Wittich | E29: monograph; text | F29: PPN767041380 | G29: PPN556113098 | H29: http://resolver.staatsbibliothek-berlin.de/SBB0000F1B600000000 | I29: ger | J29: 1819 | K29: WegehauptDigital | L29: Berlin | M29: empty | N29: no
A30: Europäische Bilder und Skizzen; zur Belehrung für die reifere Jugend | B30: Hoffmann, Julius; Hosemann, Theodor | C30: Kinder- und Jugendbücher | D30: Trewendt | E30: monograph; text | F30: PPN771014600 | G30: PPN265186358 | H30: http://resolver.staatsbibliothek-berlin.de/SBB00010A6400000000 | I30: ger | J30: 1858 | K30: WegehauptDigital | L30: Breslau | M30: https://content.staatsbibliothek-berlin.de/dc/771014600.ocr.zip | N30: yes
A31: Malerische Naturgeschichte der drei Reiche für Schule und Haus; Mit besonderer Beziehung auf das practische Leben bearbeitet von F[riedrich] W[ilhelm] Lindner; unter Mitwirkung von Dr. Fr. H. A. Lachmann | B31: Lachmann, Fr. H. A.; Lindner, Friedrich Wilhelm | C31: Kinder- und Jugendbücher; Historische Drucke | D31: Oehme & Müller | E31: monograph; text | F31: PPN770463371 | G31: PPN42077016X | H31: http://resolver.staatsbibliothek-berlin.de/SBB000104A200000000 | I31: ger | J31: 1840 | K31: WegehauptDigital | L31: Braunschweig | M31: empty | N31: no
A32: Allerlei schöne Bilderrätsel für Jung und Alt | C32: Kinder- und Jugendbücher; Historische Drucke | E32: monograph; text | F32: PPN74513548X | G32: PPN30847046X | H32: http://resolver.staatsbibliothek-berlin.de/SBB0000D5D100000000 | I32: ger | K32: WegehauptDigital | M32: https://content.staatsbibliothek-berlin.de/dc/74513548X.ocr.zip | N32: yes
A33: Der Hausbau; oder erste Begriffe von Staat und den vorzüglichsten Ständen, Handwerken, Fabriken, Künsten, Wissenschaften u. d. gl. für Kinder | B33: Werlich, August Karl Friedrich | C33: Kinder- und Jugendbücher; Historische Drucke | D33: Juniussische Buchhandlung | E33: monograph; text | F33: PPN756639891 | G33: PPN579566781 | H33: http://resolver.staatsbibliothek-berlin.de/SBB0000EB7900000000 | I33: ger | J33: 1804 | K33: WegehauptDigital | L33: Leipzig | M33: empty | N33: no
A34: Gemählde aus der Natur und dem Menschenleben, in einer Reihe von Schilderungen merkwürdiger Naturerscheinungen und gefahrvoller Reiseabentheuer; zum Nutzen und Vergnügen der Jugend | B34: Albertus, D. J. C. | C34: Kinder- und Jugendbücher | D34: Kaiser | E34: monograph; text | F34: PPN781283116 | G34: PPN541529498 | H34: http://resolver.staatsbibliothek-berlin.de/SBB0001555D00000000 | I34: ger | J34: 1830 | K34: WegehauptDigital | L34: Grätz | M34: empty | N34: no
A35: Kurzer Unterricht in der Naturwissenschaft für die Jugend | B35: Uihlein, Joseph | C35: Kinder- und Jugendbücher; Historische Drucke | D35: Andreä | E35: monograph; text | F35: PPN770157742 | G35: PPN366080202 | H35: http://resolver.staatsbibliothek-berlin.de/SBB0001033900000000 | I35: ger | J35: 1810 | K35: WegehauptDigital | L35: Frankfurt am Main | M35: empty | N35: no
A36: F. Martin's Naturgeschichte für die Jugend beiderlei Geschlechts; mit dreihundert Abbildungen und zwanzig Holzschnitten | B36: Kolb, Christian Friedrich August; Martin, F. | C36: Kinder- und Jugendbücher; Historische Drucke | D36: Schmidt & Spring | E36: monograph; text | F36: PPN741294397 | G36: PPN566740400 | H36: http://resolver.staatsbibliothek-berlin.de/SBB0000CFA500000000 | I36: ger | J36: 1880 | K36: WegehauptDigital | L36: Stuttgart | M36: https://content.staatsbibliothek-berlin.de/dc/741294397.ocr.zip | N36: yes
A37: Aus Werkstatt und Welt; eine Festgabe für die werkthätige Jugend dargereicht von Leipz. Fortbildungsschuldirektoren u.-Lehrern | C37: Kinder- und Jugendbücher; Historische Drucke | D37: Hahn; Schmidt | E37: monograph; text | F37: PPN770851347 | G37: PPN581182618 | H37: http://resolver.staatsbibliothek-berlin.de/SBB0001070300000000 | I37: ger | J37: 1901 | K37: WegehauptDigital | L37: Leipzig; Leipzig | M37: https://content.staatsbibliothek-berlin.de/dc/770851347.ocr.zip | N37: yes
A38: Mittheilungen aus dem Gebiet der Naturkunde und dem Menschenleben für die Jugend ; mit 25 col. Abb. | B38: Maukisch, Heinrich Eduard | C38: Kinder- und Jugendbücher; Historische Drucke | D38: Fischer u. Fuchs | E38: monograph; text | F38: PPN766619389 | G38: PPN566841444 | H38: http://resolver.staatsbibliothek-berlin.de/SBB0000F00A00000000 | I38: ger | J38: 1835 | K38: WegehauptDigital | L38: Leipzig | M38: empty | N38: no
A39: Čudesa bez čudesʹ; malenkaja fizika v priměnenii kʹ zabavamʹ/ sost. A. P. Nečaev. S 172 ris. | B39: Nečaev, A. P. | C39: Kinder- und Jugendbücher | D39: Lukovnikov | E39: monograph; text | F39: PPN742094227 | G39: PPN280334869 | H39: http://resolver.staatsbibliothek-berlin.de/SBB0000D0A100000000 | I39: rus | J39: 1911 | K39: WegehauptDigital | L39: Spb. [St. Petersburg] | M39: https://content.staatsbibliothek-berlin.de/dc/742094227.ocr.zip | N39: yes
A40: Nun rathe einmal!; Räthselbüchlein für Kinder von 5 - 10 Jahren | B40: Flinzer, Fedor | C40: Kinder- und Jugendbücher; Historische Drucke | D40: Focke | E40: monograph; text | F40: PPN745597041 | G40: PPN568651901 | H40: http://resolver.staatsbibliothek-berlin.de/SBB0000D6F200000000 | I40: ger | J40: 1864 | K40: WegehauptDigital | L40: Chemnitz | M40: https://content.staatsbibliothek-berlin.de/dc/745597041.ocr.zip | N40: yes
...

Sheet publishers_total
A1: language | B1: ger | O1: language | P1: ger | R1: Andere | S1: 896
R2: Spamer | S2: 85
A3: Zeilenbeschriftungen | B3: Anzahl von publisher | O3: Zeilenbeschriftungen | P3: Anzahl von publisher | R3: Fleischer | S3: 36
A4: Andere | B4: 896 | O4: May | P4: 1 | R4: Industrie-Comptoir | S4: 31
A5: Spamer | B5: 85 | O5: [Basedow] | P5: 3 | R5: Arnold | S5: 24
A6: Fleischer | B6: 36 | O6: A. W. Hayn's Erben | P6: 1 | R6: Schreiber | S6: 23
A7: Industrie-Comptoir | B7: 31 | O7: A. Weichert | P7: 1 | R7: Grözinger | S7: 20
A8: Arnold | B8: 24 | O8: Adler | P8: 1 | R8: Teubner | S8: 20
A9: Schreiber | B9: 23 | O9: Agentur des Rauhen Hauses | P9: 1 | R9: Barth | S9: 18
A10: Grözinger | B10: 20 | O10: Amelang | P10: 16 | R10: Oehmigke | S10: 18
A11: Teubner | B11: 20 | O11: Andrea | P11: 1 | R11: Campe | S11: 18
A12: Campe | B12: 18 | O12: Andreä | P12: 1 | R12: Velhagen & Klasing | S12: 16
A13: Oehmigke | B13: 18 | O13: Andreäische Buchhandlung | P13: 1 | R13: Amelang | S13: 16
A14: Barth | B14: 18 | O14: Anich | P14: 1 | R14: Monath | S14: 16
A15: Velhagen & Klasing | B15: 16 | O15: Anton | P15: 1 | R15: Hoffmann | S15: 15
... A24: Wilmans | B24: 11 | O24: Bagel | P24: 9 | R24: Dieterich | S24: 10
A25: Vogel | B25: 11 | O25: Bagel] | P25: 1
A26: Flemming | B26: 10 | O26: Balz | P26: 6
A27: Dieterich | B27: 10 | O27: Balz und Schramm | P27: 2
A28: Gesamtergebnis | B28: 1358 | O28: Barth | P28: 18
O29: Barth & Hamberger | P29: 1
O30: Bartholomäi | P30: 1
O31: Bartholomäus | P31: 2
O32: Basse | P32: 2
O33: Bauer u. Raspe | P33: 1
O34: Bauer und Raspe | P34: 2
O35: Baukasten-Verl.] | P35: 2
O36: Baumeister | P36: 6
O37: Baumgaertner | P37: 1
O38: Baumgärtner | P38: 3
O39: Beck | P39: 2
O40: Benziger | P40: 1
... O498: Zieger | P498: 2
O499: (Leer)
O500: Gesamtergebnis | P500: 1358

Sheet languages
A1: Zeilenbeschriftungen | B1: Anzahl von language
A2: ger | B2: 1401
A3: fre | B3: 160
A4: eng | B4: 65
A5: lat | B5: 9
A6: rus | B6: 4
A7: ita | B7: 4
A8: dut | B8: 2
A9: dan | B9: 1
A10: swe | B10: 1
A11: pol | B11: 1
A12: Gesamtergebnis | B12: 1648
A14: Zeilenbeschriftungen | B14: Anzahl von language
A15: ger | B15: 1401
A16: no | B16: 803
A17: yes | B17: 598
A18: fre | B18: 160
A19: no | B19: 129
A20: yes | B20: 31
A21: eng | B21: 65
A22: no | B22: 34
A23: yes | B23: 31
A24: lat | B24: 9
A25: no | B25: 9
A26: rus | B26: 4
... A38: Gesamtergebnis | B38: 1648
A40: Zeilenbeschriftungen | B40: Anzahl von language
A41: dan | B41: 1
A42: dut | B42: 2
A43: eng | B43: 65
A44: fre | B44: 160
A45: fre; ger; lat; ita | B45: 1
A46: fre; lat; rus; ger; ita | B46: 1
A47: ger | B47: 1401
A48: ger; fre | B48: 10
A49: ger; fre; eng; ita | B49: 2
A50: ita | B50: 4
A51: lat | B51: 9
A52: lat; cze; ger; fre | B52: 1
... A57: swe | B57: 1
...

Sheet OCR_ger
A1: title | B1: creator | C1: subject | D1: publisher | E1: type | F1: digital object identifier | G1: physical object identifier | H1: URL | I1: language | J1: date | K1: relation | L1: coverage | M1: OCR URL | N1: OCR found?
A2: Abrégé de toutes les sciences, ou encyclopédie des enfants; mise dans un nouvel ordre,... | B2: Buqcellos, ...; Blocquel, Simon | C2: Kinder- und Jugendbücher; Historische Drucke | D2: Delarue ;; Castiaux | E2: monograph; text | F2: PPN766849139 | G2: PPN548262071 | H2: http://resolver.staatsbibliothek-berlin.de/SBB0000F13000000000 | I2: fre | J2: 1816 | K2: WegehauptDigital | L2: Paris; Lille | M2: empty | N2: no
A3: Naturgeschichte für Kinder | B3: Raff, Georg Christian | C3: Kinder- und Jugendbücher; Historische Drucke | D3: Sammer | E3: monograph; text | F3: PPN749770333 | G3: PPN279536941 | H3: http://resolver.staatsbibliothek-berlin.de/SBB0000E0AE00000000 | I3: ger | J3: 1846 | K3: WegehauptDigital | L3: Wien | M3: empty | N3: no
